<?xml version="1.0" ?>
<!-- =================================================================================== -->
<!-- |    This document was autogenerated by xacro from model.xacro                    | -->
<!-- |    EDITING THIS FILE BY HAND IS NOT RECOMMENDED                                 | -->
<!-- =================================================================================== -->
<robot name="tether_2m">
  <!-- <xacro:property name="joint_effort"   value="1000" />
  <xacro:property name="joint_velocity" value="1000" /> -->
  <link name="element_29">
    <inertial>
      <origin rpy="0 0 0" xyz="0 0 0.04174137931034482"/>
      <mass value="0.0006896551724137932"/>
      <inertia ixx="4.021954590184098e-07" ixy="0" ixz="0" iyy="4.021954590184098e-07" iyz="0" izz="3.313793103448276e-09"/>
    </inertial>
    <visual>
      <origin rpy="0 0 0" xyz="0 0 0.04174137931034482"/>
      <geometry>
        <cylinder length="0.08348275862068964" radius="0.0031"/>
      </geometry>
    </visual>
    <!-- <collision>
        <origin xyz="0 0 ${elem_length/2}" rpy="0 0 0"/>
        <geometry>
          <cylinder length="${elem_length}" radius="0.0031"/>
        </geometry>
      </collision> -->
  </link>
  <link name="element_28">
    <inertial>
      <origin rpy="0 0 0" xyz="0 0 0.04174137931034482"/>
      <mass value="0.0006896551724137932"/>
      <inertia ixx="4.021954590184098e-07" ixy="0" ixz="0" iyy="4.021954590184098e-07" iyz="0" izz="3.313793103448276e-09"/>
    </inertial>
    <visual>
      <origin rpy="0 0 0" xyz="0 0 0.04174137931034482"/>
      <geometry>
        <cylinder length="0.08348275862068964" radius="0.0031"/>
      </geometry>
    </visual>
    <!-- <collision>
        <origin xyz="0 0 ${elem_length/2}" rpy="0 0 0"/>
        <geometry>
          <cylinder length="${elem_length}" radius="0.0031"/>
        </geometry>
      </collision> -->
  </link>
  <link name="element_27">
    <inertial>
      <origin rpy="0 0 0" xyz="0 0 0.04174137931034482"/>
      <mass value="0.0006896551724137932"/>
      <inertia ixx="4.021954590184098e-07" ixy="0" ixz="0" iyy="4.021954590184098e-07" iyz="0" izz="3.313793103448276e-09"/>
    </inertial>
    <visual>
      <origin rpy="0 0 0" xyz="0 0 0.04174137931034482"/>
      <geometry>
        <cylinder length="0.08348275862068964" radius="0.0031"/>
      </geometry>
    </visual>
    <!-- <collision>
        <origin xyz="0 0 ${elem_length/2}" rpy="0 0 0"/>
        <geometry>
          <cylinder length="${elem_length}" radius="0.0031"/>
        </geometry>
      </collision> -->
  </link>
  <link name="element_26">
    <inertial>
      <origin rpy="0 0 0" xyz="0 0 0.04174137931034482"/>
      <mass value="0.0006896551724137932"/>
      <inertia ixx="4.021954590184098e-07" ixy="0" ixz="0" iyy="4.021954590184098e-07" iyz="0" izz="3.313793103448276e-09"/>
    </inertial>
    <visual>
      <origin rpy="0 0 0" xyz="0 0 0.04174137931034482"/>
      <geometry>
        <cylinder length="0.08348275862068964" radius="0.0031"/>
      </geometry>
    </visual>
    <!-- <collision>
        <origin xyz="0 0 ${elem_length/2}" rpy="0 0 0"/>
        <geometry>
          <cylinder length="${elem_length}" radius="0.0031"/>
        </geometry>
      </collision> -->
  </link>
  <link name="element_25">
    <inertial>
      <origin rpy="0 0 0" xyz="0 0 0.04174137931034482"/>
      <mass value="0.0006896551724137932"/>
      <inertia ixx="4.021954590184098e-07" ixy="0" ixz="0" iyy="4.021954590184098e-07" iyz="0" izz="3.313793103448276e-09"/>
    </inertial>
    <visual>
      <origin rpy="0 0 0" xyz="0 0 0.04174137931034482"/>
      <geometry>
        <cylinder length="0.08348275862068964" radius="0.0031"/>
      </geometry>
    </visual>
    <!-- <collision>
        <origin xyz="0 0 ${elem_length/2}" rpy="0 0 0"/>
        <geometry>
          <cylinder length="${elem_length}" radius="0.0031"/>
        </geometry>
      </collision> -->
  </link>
  <link name="element_24">
    <inertial>
      <origin rpy="0 0 0" xyz="0 0 0.04174137931034482"/>
      <mass value="0.0006896551724137932"/>
      <inertia ixx="4.021954590184098e-07" ixy="0" ixz="0" iyy="4.021954590184098e-07" iyz="0" izz="3.313793103448276e-09"/>
    </inertial>
    <visual>
      <origin rpy="0 0 0" xyz="0 0 0.04174137931034482"/>
      <geometry>
        <cylinder length="0.08348275862068964" radius="0.0031"/>
      </geometry>
    </visual>
    <!-- <collision>
        <origin xyz="0 0 ${elem_length/2}" rpy="0 0 0"/>
        <geometry>
          <cylinder length="${elem_length}" radius="0.0031"/>
        </geometry>
      </collision> -->
  </link>
  <link name="element_23">
    <inertial>
      <origin rpy="0 0 0" xyz="0 0 0.04174137931034482"/>
      <mass value="0.0006896551724137932"/>
      <inertia ixx="4.021954590184098e-07" ixy="0" ixz="0" iyy="4.021954590184098e-07" iyz="0" izz="3.313793103448276e-09"/>
    </inertial>
    <visual>
      <origin rpy="0 0 0" xyz="0 0 0.04174137931034482"/>
      <geometry>
        <cylinder length="0.08348275862068964" radius="0.0031"/>
      </geometry>
    </visual>
    <!-- <collision>
        <origin xyz="0 0 ${elem_length/2}" rpy="0 0 0"/>
        <geometry>
          <cylinder length="${elem_length}" radius="0.0031"/>
        </geometry>
      </collision> -->
  </link>
  <link name="element_22">
    <inertial>
      <origin rpy="0 0 0" xyz="0 0 0.04174137931034482"/>
      <mass value="0.0006896551724137932"/>
      <inertia ixx="4.021954590184098e-07" ixy="0" ixz="0" iyy="4.021954590184098e-07" iyz="0" izz="3.313793103448276e-09"/>
    </inertial>
    <visual>
      <origin rpy="0 0 0" xyz="0 0 0.04174137931034482"/>
      <geometry>
        <cylinder length="0.08348275862068964" radius="0.0031"/>
      </geometry>
    </visual>
    <!-- <collision>
        <origin xyz="0 0 ${elem_length/2}" rpy="0 0 0"/>
        <geometry>
          <cylinder length="${elem_length}" radius="0.0031"/>
        </geometry>
      </collision> -->
  </link>
  <link name="element_21">
    <inertial>
      <origin rpy="0 0 0" xyz="0 0 0.04174137931034482"/>
      <mass value="0.0006896551724137932"/>
      <inertia ixx="4.021954590184098e-07" ixy="0" ixz="0" iyy="4.021954590184098e-07" iyz="0" izz="3.313793103448276e-09"/>
    </inertial>
    <visual>
      <origin rpy="0 0 0" xyz="0 0 0.04174137931034482"/>
      <geometry>
        <cylinder length="0.08348275862068964" radius="0.0031"/>
      </geometry>
    </visual>
    <!-- <collision>
        <origin xyz="0 0 ${elem_length/2}" rpy="0 0 0"/>
        <geometry>
          <cylinder length="${elem_length}" radius="0.0031"/>
        </geometry>
      </collision> -->
  </link>
  <link name="element_20">
    <inertial>
      <origin rpy="0 0 0" xyz="0 0 0.04174137931034482"/>
      <mass value="0.0006896551724137932"/>
      <inertia ixx="4.021954590184098e-07" ixy="0" ixz="0" iyy="4.021954590184098e-07" iyz="0" izz="3.313793103448276e-09"/>
    </inertial>
    <visual>
      <origin rpy="0 0 0" xyz="0 0 0.04174137931034482"/>
      <geometry>
        <cylinder length="0.08348275862068964" radius="0.0031"/>
      </geometry>
    </visual>
    <!-- <collision>
        <origin xyz="0 0 ${elem_length/2}" rpy="0 0 0"/>
        <geometry>
          <cylinder length="${elem_length}" radius="0.0031"/>
        </geometry>
      </collision> -->
  </link>
  <link name="element_19">
    <inertial>
      <origin rpy="0 0 0" xyz="0 0 0.04174137931034482"/>
      <mass value="0.0006896551724137932"/>
      <inertia ixx="4.021954590184098e-07" ixy="0" ixz="0" iyy="4.021954590184098e-07" iyz="0" izz="3.313793103448276e-09"/>
    </inertial>
    <visual>
      <origin rpy="0 0 0" xyz="0 0 0.04174137931034482"/>
      <geometry>
        <cylinder length="0.08348275862068964" radius="0.0031"/>
      </geometry>
    </visual>
    <!-- <collision>
        <origin xyz="0 0 ${elem_length/2}" rpy="0 0 0"/>
        <geometry>
          <cylinder length="${elem_length}" radius="0.0031"/>
        </geometry>
      </collision> -->
  </link>
  <link name="element_18">
    <inertial>
      <origin rpy="0 0 0" xyz="0 0 0.04174137931034482"/>
      <mass value="0.0006896551724137932"/>
      <inertia ixx="4.021954590184098e-07" ixy="0" ixz="0" iyy="4.021954590184098e-07" iyz="0" izz="3.313793103448276e-09"/>
    </inertial>
    <visual>
      <origin rpy="0 0 0" xyz="0 0 0.04174137931034482"/>
      <geometry>
        <cylinder length="0.08348275862068964" radius="0.0031"/>
      </geometry>
    </visual>
    <!-- <collision>
        <origin xyz="0 0 ${elem_length/2}" rpy="0 0 0"/>
        <geometry>
          <cylinder length="${elem_length}" radius="0.0031"/>
        </geometry>
      </collision> -->
  </link>
  <link name="element_17">
    <inertial>
      <origin rpy="0 0 0" xyz="0 0 0.04174137931034482"/>
      <mass value="0.0006896551724137932"/>
      <inertia ixx="4.021954590184098e-07" ixy="0" ixz="0" iyy="4.021954590184098e-07" iyz="0" izz="3.313793103448276e-09"/>
    </inertial>
    <visual>
      <origin rpy="0 0 0" xyz="0 0 0.04174137931034482"/>
      <geometry>
        <cylinder length="0.08348275862068964" radius="0.0031"/>
      </geometry>
    </visual>
    <!-- <collision>
        <origin xyz="0 0 ${elem_length/2}" rpy="0 0 0"/>
        <geometry>
          <cylinder length="${elem_length}" radius="0.0031"/>
        </geometry>
      </collision> -->
  </link>
  <link name="element_16">
    <inertial>
      <origin rpy="0 0 0" xyz="0 0 0.04174137931034482"/>
      <mass value="0.0006896551724137932"/>
      <inertia ixx="4.021954590184098e-07" ixy="0" ixz="0" iyy="4.021954590184098e-07" iyz="0" izz="3.313793103448276e-09"/>
    </inertial>
    <visual>
      <origin rpy="0 0 0" xyz="0 0 0.04174137931034482"/>
      <geometry>
        <cylinder length="0.08348275862068964" radius="0.0031"/>
      </geometry>
    </visual>
    <!-- <collision>
        <origin xyz="0 0 ${elem_length/2}" rpy="0 0 0"/>
        <geometry>
          <cylinder length="${elem_length}" radius="0.0031"/>
        </geometry>
      </collision> -->
  </link>
  <link name="element_15">
    <inertial>
      <origin rpy="0 0 0" xyz="0 0 0.04174137931034482"/>
      <mass value="0.0006896551724137932"/>
      <inertia ixx="4.021954590184098e-07" ixy="0" ixz="0" iyy="4.021954590184098e-07" iyz="0" izz="3.313793103448276e-09"/>
    </inertial>
    <visual>
      <origin rpy="0 0 0" xyz="0 0 0.04174137931034482"/>
      <geometry>
        <cylinder length="0.08348275862068964" radius="0.0031"/>
      </geometry>
    </visual>
    <!-- <collision>
        <origin xyz="0 0 ${elem_length/2}" rpy="0 0 0"/>
        <geometry>
          <cylinder length="${elem_length}" radius="0.0031"/>
        </geometry>
      </collision> -->
  </link>
  <link name="element_14">
    <inertial>
      <origin rpy="0 0 0" xyz="0 0 0.04174137931034482"/>
      <mass value="0.0006896551724137932"/>
      <inertia ixx="4.021954590184098e-07" ixy="0" ixz="0" iyy="4.021954590184098e-07" iyz="0" izz="3.313793103448276e-09"/>
    </inertial>
    <visual>
      <origin rpy="0 0 0" xyz="0 0 0.04174137931034482"/>
      <geometry>
        <cylinder length="0.08348275862068964" radius="0.0031"/>
      </geometry>
    </visual>
    <!-- <collision>
        <origin xyz="0 0 ${elem_length/2}" rpy="0 0 0"/>
        <geometry>
          <cylinder length="${elem_length}" radius="0.0031"/>
        </geometry>
      </collision> -->
  </link>
  <link name="element_13">
    <inertial>
      <origin rpy="0 0 0" xyz="0 0 0.04174137931034482"/>
      <mass value="0.0006896551724137932"/>
      <inertia ixx="4.021954590184098e-07" ixy="0" ixz="0" iyy="4.021954590184098e-07" iyz="0" izz="3.313793103448276e-09"/>
    </inertial>
    <visual>
      <origin rpy="0 0 0" xyz="0 0 0.04174137931034482"/>
      <geometry>
        <cylinder length="0.08348275862068964" radius="0.0031"/>
      </geometry>
    </visual>
    <!-- <collision>
        <origin xyz="0 0 ${elem_length/2}" rpy="0 0 0"/>
        <geometry>
          <cylinder length="${elem_length}" radius="0.0031"/>
        </geometry>
      </collision> -->
  </link>
  <link name="element_12">
    <inertial>
      <origin rpy="0 0 0" xyz="0 0 0.04174137931034482"/>
      <mass value="0.0006896551724137932"/>
      <inertia ixx="4.021954590184098e-07" ixy="0" ixz="0" iyy="4.021954590184098e-07" iyz="0" izz="3.313793103448276e-09"/>
    </inertial>
    <visual>
      <origin rpy="0 0 0" xyz="0 0 0.04174137931034482"/>
      <geometry>
        <cylinder length="0.08348275862068964" radius="0.0031"/>
      </geometry>
    </visual>
    <!-- <collision>
        <origin xyz="0 0 ${elem_length/2}" rpy="0 0 0"/>
        <geometry>
          <cylinder length="${elem_length}" radius="0.0031"/>
        </geometry>
      </collision> -->
  </link>
  <link name="element_11">
    <inertial>
      <origin rpy="0 0 0" xyz="0 0 0.04174137931034482"/>
      <mass value="0.0006896551724137932"/>
      <inertia ixx="4.021954590184098e-07" ixy="0" ixz="0" iyy="4.021954590184098e-07" iyz="0" izz="3.313793103448276e-09"/>
    </inertial>
    <visual>
      <origin rpy="0 0 0" xyz="0 0 0.04174137931034482"/>
      <geometry>
        <cylinder length="0.08348275862068964" radius="0.0031"/>
      </geometry>
    </visual>
    <!-- <collision>
        <origin xyz="0 0 ${elem_length/2}" rpy="0 0 0"/>
        <geometry>
          <cylinder length="${elem_length}" radius="0.0031"/>
        </geometry>
      </collision> -->
  </link>
  <link name="element_10">
    <inertial>
      <origin rpy="0 0 0" xyz="0 0 0.04174137931034482"/>
      <mass value="0.0006896551724137932"/>
      <inertia ixx="4.021954590184098e-07" ixy="0" ixz="0" iyy="4.021954590184098e-07" iyz="0" izz="3.313793103448276e-09"/>
    </inertial>
    <visual>
      <origin rpy="0 0 0" xyz="0 0 0.04174137931034482"/>
      <geometry>
        <cylinder length="0.08348275862068964" radius="0.0031"/>
      </geometry>
    </visual>
    <!-- <collision>
        <origin xyz="0 0 ${elem_length/2}" rpy="0 0 0"/>
        <geometry>
          <cylinder length="${elem_length}" radius="0.0031"/>
        </geometry>
      </collision> -->
  </link>
  <link name="element_9">
    <inertial>
      <origin rpy="0 0 0" xyz="0 0 0.04174137931034482"/>
      <mass value="0.0006896551724137932"/>
      <inertia ixx="4.021954590184098e-07" ixy="0" ixz="0" iyy="4.021954590184098e-07" iyz="0" izz="3.313793103448276e-09"/>
    </inertial>
    <visual>
      <origin rpy="0 0 0" xyz="0 0 0.04174137931034482"/>
      <geometry>
        <cylinder length="0.08348275862068964" radius="0.0031"/>
      </geometry>
    </visual>
    <!-- <collision>
        <origin xyz="0 0 ${elem_length/2}" rpy="0 0 0"/>
        <geometry>
          <cylinder length="${elem_length}" radius="0.0031"/>
        </geometry>
      </collision> -->
  </link>
  <link name="element_8">
    <inertial>
      <origin rpy="0 0 0" xyz="0 0 0.04174137931034482"/>
      <mass value="0.0006896551724137932"/>
      <inertia ixx="4.021954590184098e-07" ixy="0" ixz="0" iyy="4.021954590184098e-07" iyz="0" izz="3.313793103448276e-09"/>
    </inertial>
    <visual>
      <origin rpy="0 0 0" xyz="0 0 0.04174137931034482"/>
      <geometry>
        <cylinder length="0.08348275862068964" radius="0.0031"/>
      </geometry>
    </visual>
    <!-- <collision>
        <origin xyz="0 0 ${elem_length/2}" rpy="0 0 0"/>
        <geometry>
          <cylinder length="${elem_length}" radius="0.0031"/>
        </geometry>
      </collision> -->
  </link>
  <link name="element_7">
    <inertial>
      <origin rpy="0 0 0" xyz="0 0 0.04174137931034482"/>
      <mass value="0.0006896551724137932"/>
      <inertia ixx="4.021954590184098e-07" ixy="0" ixz="0" iyy="4.021954590184098e-07" iyz="0" izz="3.313793103448276e-09"/>
    </inertial>
    <visual>
      <origin rpy="0 0 0" xyz="0 0 0.04174137931034482"/>
      <geometry>
        <cylinder length="0.08348275862068964" radius="0.0031"/>
      </geometry>
    </visual>
    <!-- <collision>
        <origin xyz="0 0 ${elem_length/2}" rpy="0 0 0"/>
        <geometry>
          <cylinder length="${elem_length}" radius="0.0031"/>
        </geometry>
      </collision> -->
  </link>
  <link name="element_6">
    <inertial>
      <origin rpy="0 0 0" xyz="0 0 0.04174137931034482"/>
      <mass value="0.0006896551724137932"/>
      <inertia ixx="4.021954590184098e-07" ixy="0" ixz="0" iyy="4.021954590184098e-07" iyz="0" izz="3.313793103448276e-09"/>
    </inertial>
    <visual>
      <origin rpy="0 0 0" xyz="0 0 0.04174137931034482"/>
      <geometry>
        <cylinder length="0.08348275862068964" radius="0.0031"/>
      </geometry>
    </visual>
    <!-- <collision>
        <origin xyz="0 0 ${elem_length/2}" rpy="0 0 0"/>
        <geometry>
          <cylinder length="${elem_length}" radius="0.0031"/>
        </geometry>
      </collision> -->
  </link>
  <link name="element_5">
    <inertial>
      <origin rpy="0 0 0" xyz="0 0 0.04174137931034482"/>
      <mass value="0.0006896551724137932"/>
      <inertia ixx="4.021954590184098e-07" ixy="0" ixz="0" iyy="4.021954590184098e-07" iyz="0" izz="3.313793103448276e-09"/>
    </inertial>
    <visual>
      <origin rpy="0 0 0" xyz="0 0 0.04174137931034482"/>
      <geometry>
        <cylinder length="0.08348275862068964" radius="0.0031"/>
      </geometry>
    </visual>
    <!-- <collision>
        <origin xyz="0 0 ${elem_length/2}" rpy="0 0 0"/>
        <geometry>
          <cylinder length="${elem_length}" radius="0.0031"/>
        </geometry>
      </collision> -->
  </link>
  <link name="element_4">
    <inertial>
      <origin rpy="0 0 0" xyz="0 0 0.04174137931034482"/>
      <mass value="0.0006896551724137932"/>
      <inertia ixx="4.021954590184098e-07" ixy="0" ixz="0" iyy="4.021954590184098e-07" iyz="0" izz="3.313793103448276e-09"/>
    </inertial>
    <visual>
      <origin rpy="0 0 0" xyz="0 0 0.04174137931034482"/>
      <geometry>
        <cylinder length="0.08348275862068964" radius="0.0031"/>
      </geometry>
    </visual>
    <!-- <collision>
        <origin xyz="0 0 ${elem_length/2}" rpy="0 0 0"/>
        <geometry>
          <cylinder length="${elem_length}" radius="0.0031"/>
        </geometry>
      </collision> -->
  </link>
  <link name="element_3">
    <inertial>
      <origin rpy="0 0 0" xyz="0 0 0.04174137931034482"/>
      <mass value="0.0006896551724137932"/>
      <inertia ixx="4.021954590184098e-07" ixy="0" ixz="0" iyy="4.021954590184098e-07" iyz="0" izz="3.313793103448276e-09"/>
    </inertial>
    <visual>
      <origin rpy="0 0 0" xyz="0 0 0.04174137931034482"/>
      <geometry>
        <cylinder length="0.08348275862068964" radius="0.0031"/>
      </geometry>
    </visual>
    <!-- <collision>
        <origin xyz="0 0 ${elem_length/2}" rpy="0 0 0"/>
        <geometry>
          <cylinder length="${elem_length}" radius="0.0031"/>
        </geometry>
      </collision> -->
  </link>
  <link name="element_2">
    <inertial>
      <origin rpy="0 0 0" xyz="0 0 0.04174137931034482"/>
      <mass value="0.0006896551724137932"/>
      <inertia ixx="4.021954590184098e-07" ixy="0" ixz="0" iyy="4.021954590184098e-07" iyz="0" izz="3.313793103448276e-09"/>
    </inertial>
    <visual>
      <origin rpy="0 0 0" xyz="0 0 0.04174137931034482"/>
      <geometry>
        <cylinder length="0.08348275862068964" radius="0.0031"/>
      </geometry>
    </visual>
    <!-- <collision>
        <origin xyz="0 0 ${elem_length/2}" rpy="0 0 0"/>
        <geometry>
          <cylinder length="${elem_length}" radius="0.0031"/>
        </geometry>
      </collision> -->
  </link>
  <link name="element_1">
    <inertial>
      <origin rpy="0 0 0" xyz="0 0 0.04174137931034482"/>
      <mass value="0.0006896551724137932"/>
      <inertia ixx="4.021954590184098e-07" ixy="0" ixz="0" iyy="4.021954590184098e-07" iyz="0" izz="3.313793103448276e-09"/>
    </inertial>
    <visual>
      <origin rpy="0 0 0" xyz="0 0 0.04174137931034482"/>
      <geometry>
        <cylinder length="0.08348275862068964" radius="0.0031"/>
      </geometry>
    </visual>
    <!-- <collision>
        <origin xyz="0 0 ${elem_length/2}" rpy="0 0 0"/>
        <geometry>
          <cylinder length="${elem_length}" radius="0.0031"/>
        </geometry>
      </collision> -->
  </link>
  <joint name="joint_1_to_2" type="continuous">
    <axis xyz="0 1 0">
      <!-- <limit effort="${joint_effort}" velocity="${joint_velocity}"/> -->
      <dynamics damping="0.005" friction="0"/>
    </axis>
    <origin rpy="0 0 0" xyz="0 0 0.08348275862068964"/>
    <parent link="element_1"/>
    <child link="element_2"/>
  </joint>
  <joint name="joint_2_to_3" type="continuous">
    <axis xyz="0 1 0">
      <!-- <limit effort="${joint_effort}" velocity="${joint_velocity}"/> -->
      <dynamics damping="0.005" friction="0"/>
    </axis>
    <origin rpy="0 0 0" xyz="0 0 0.08348275862068964"/>
    <parent link="element_2"/>
    <child link="element_3"/>
  </joint>
  <joint name="joint_3_to_4" type="continuous">
    <axis xyz="0 1 0">
      <!-- <limit effort="${joint_effort}" velocity="${joint_velocity}"/> -->
      <dynamics damping="0.005" friction="0"/>
    </axis>
    <origin rpy="0 0 0" xyz="0 0 0.08348275862068964"/>
    <parent link="element_3"/>
    <child link="element_4"/>
  </joint>
  <joint name="joint_4_to_5" type="continuous">
    <axis xyz="0 1 0">
      <!-- <limit effort="${joint_effort}" velocity="${joint_velocity}"/> -->
      <dynamics damping="0.005" friction="0"/>
    </axis>
    <origin rpy="0 0 0" xyz="0 0 0.08348275862068964"/>
    <parent link="element_4"/>
    <child link="element_5"/>
  </joint>
  <joint name="joint_5_to_6" type="continuous">
    <axis xyz="0 1 0">
      <!-- <limit effort="${joint_effort}" velocity="${joint_velocity}"/> -->
      <dynamics damping="0.005" friction="0"/>
    </axis>
    <origin rpy="0 0 0" xyz="0 0 0.08348275862068964"/>
    <parent link="element_5"/>
    <child link="element_6"/>
  </joint>
  <joint name="joint_6_to_7" type="continuous">
    <axis xyz="0 1 0">
      <!-- <limit effort="${joint_effort}" velocity="${joint_velocity}"/> -->
      <dynamics damping="0.005" friction="0"/>
    </axis>
    <origin rpy="0 0 0" xyz="0 0 0.08348275862068964"/>
    <parent link="element_6"/>
    <child link="element_7"/>
  </joint>
  <joint name="joint_7_to_8" type="continuous">
    <axis xyz="0 1 0">
      <!-- <limit effort="${joint_effort}" velocity="${joint_velocity}"/> -->
      <dynamics damping="0.005" friction="0"/>
    </axis>
    <origin rpy="0 0 0" xyz="0 0 0.08348275862068964"/>
    <parent link="element_7"/>
    <child link="element_8"/>
  </joint>
  <joint name="joint_8_to_9" type="continuous">
    <axis xyz="0 1 0">
      <!-- <limit effort="${joint_effort}" velocity="${joint_velocity}"/> -->
      <dynamics damping="0.005" friction="0"/>
    </axis>
    <origin rpy="0 0 0" xyz="0 0 0.08348275862068964"/>
    <parent link="element_8"/>
    <child link="element_9"/>
  </joint>
  <joint name="joint_9_to_10" type="continuous">
    <axis xyz="0 1 0">
      <!-- <limit effort="${joint_effort}" velocity="${joint_velocity}"/> -->
      <dynamics damping="0.005" friction="0"/>
    </axis>
    <origin rpy="0 0 0" xyz="0 0 0.08348275862068964"/>
    <parent link="element_9"/>
    <child link="element_10"/>
  </joint>
  <joint name="joint_10_to_11" type="continuous">
    <axis xyz="0 1 0">
      <!-- <limit effort="${joint_effort}" velocity="${joint_velocity}"/> -->
      <dynamics damping="0.005" friction="0"/>
    </axis>
    <origin rpy="0 0 0" xyz="0 0 0.08348275862068964"/>
    <parent link="element_10"/>
    <child link="element_11"/>
  </joint>
  <joint name="joint_11_to_12" type="continuous">
    <axis xyz="0 1 0">
      <!-- <limit effort="${joint_effort}" velocity="${joint_velocity}"/> -->
      <dynamics damping="0.005" friction="0"/>
    </axis>
    <origin rpy="0 0 0" xyz="0 0 0.08348275862068964"/>
    <parent link="element_11"/>
    <child link="element_12"/>
  </joint>
  <joint name="joint_12_to_13" type="continuous">
    <axis xyz="0 1 0">
      <!-- <limit effort="${joint_effort}" velocity="${joint_velocity}"/> -->
      <dynamics damping="0.005" friction="0"/>
    </axis>
    <origin rpy="0 0 0" xyz="0 0 0.08348275862068964"/>
    <parent link="element_12"/>
    <child link="element_13"/>
  </joint>
  <joint name="joint_13_to_14" type="continuous">
    <axis xyz="0 1 0">
      <!-- <limit effort="${joint_effort}" velocity="${joint_velocity}"/> -->
      <dynamics damping="0.005" friction="0"/>
    </axis>
    <origin rpy="0 0 0" xyz="0 0 0.08348275862068964"/>
    <parent link="element_13"/>
    <child link="element_14"/>
  </joint>
  <joint name="joint_14_to_15" type="continuous">
    <axis xyz="0 1 0">
      <!-- <limit effort="${joint_effort}" velocity="${joint_velocity}"/> -->
      <dynamics damping="0.005" friction="0"/>
    </axis>
    <origin rpy="0 0 0" xyz="0 0 0.08348275862068964"/>
    <parent link="element_14"/>
    <child link="element_15"/>
  </joint>
  <joint name="joint_15_to_16" type="continuous">
    <axis xyz="0 1 0">
      <!-- <limit effort="${joint_effort}" velocity="${joint_velocity}"/> -->
      <dynamics damping="0.005" friction="0"/>
    </axis>
    <origin rpy="0 0 0" xyz="0 0 0.08348275862068964"/>
    <parent link="element_15"/>
    <child link="element_16"/>
  </joint>
  <joint name="joint_16_to_17" type="continuous">
    <axis xyz="0 1 0">
      <!-- <limit effort="${joint_effort}" velocity="${joint_velocity}"/> -->
      <dynamics damping="0.005" friction="0"/>
    </axis>
    <origin rpy="0 0 0" xyz="0 0 0.08348275862068964"/>
    <parent link="element_16"/>
    <child link="element_17"/>
  </joint>
  <joint name="joint_17_to_18" type="continuous">
    <axis xyz="0 1 0">
      <!-- <limit effort="${joint_effort}" velocity="${joint_velocity}"/> -->
      <dynamics damping="0.005" friction="0"/>
    </axis>
    <origin rpy="0 0 0" xyz="0 0 0.08348275862068964"/>
    <parent link="element_17"/>
    <child link="element_18"/>
  </joint>
  <joint name="joint_18_to_19" type="continuous">
    <axis xyz="0 1 0">
      <!-- <limit effort="${joint_effort}" velocity="${joint_velocity}"/> -->
      <dynamics damping="0.005" friction="0"/>
    </axis>
    <origin rpy="0 0 0" xyz="0 0 0.08348275862068964"/>
    <parent link="element_18"/>
    <child link="element_19"/>
  </joint>
  <joint name="joint_19_to_20" type="continuous">
    <axis xyz="0 1 0">
      <!-- <limit effort="${joint_effort}" velocity="${joint_velocity}"/> -->
      <dynamics damping="0.005" friction="0"/>
    </axis>
    <origin rpy="0 0 0" xyz="0 0 0.08348275862068964"/>
    <parent link="element_19"/>
    <child link="element_20"/>
  </joint>
  <joint name="joint_20_to_21" type="continuous">
    <axis xyz="0 1 0">
      <!-- <limit effort="${joint_effort}" velocity="${joint_velocity}"/> -->
      <dynamics damping="0.005" friction="0"/>
    </axis>
    <origin rpy="0 0 0" xyz="0 0 0.08348275862068964"/>
    <parent link="element_20"/>
    <child link="element_21"/>
  </joint>
  <joint name="joint_21_to_22" type="continuous">
    <axis xyz="0 1 0">
      <!-- <limit effort="${joint_effort}" velocity="${joint_velocity}"/> -->
      <dynamics damping="0.005" friction="0"/>
    </axis>
    <origin rpy="0 0 0" xyz="0 0 0.08348275862068964"/>
    <parent link="element_21"/>
    <child link="element_22"/>
  </joint>
  <joint name="joint_22_to_23" type="continuous">
    <axis xyz="0 1 0">
      <!-- <limit effort="${joint_effort}" velocity="${joint_velocity}"/> -->
      <dynamics damping="0.005" friction="0"/>
    </axis>
    <origin rpy="0 0 0" xyz="0 0 0.08348275862068964"/>
    <parent link="element_22"/>
    <child link="element_23"/>
  </joint>
  <joint name="joint_23_to_24" type="continuous">
    <axis xyz="0 1 0">
      <!-- <limit effort="${joint_effort}" velocity="${joint_velocity}"/> -->
      <dynamics damping="0.005" friction="0"/>
    </axis>
    <origin rpy="0 0 0" xyz="0 0 0.08348275862068964"/>
    <parent link="element_23"/>
    <child link="element_24"/>
  </joint>
  <joint name="joint_24_to_25" type="continuous">
    <axis xyz="0 1 0">
      <!-- <limit effort="${joint_effort}" velocity="${joint_velocity}"/> -->
      <dynamics damping="0.005" friction="0"/>
    </axis>
    <origin rpy="0 0 0" xyz="0 0 0.08348275862068964"/>
    <parent link="element_24"/>
    <child link="element_25"/>
  </joint>
  <joint name="joint_25_to_26" type="continuous">
    <axis xyz="0 1 0">
      <!-- <limit effort="${joint_effort}" velocity="${joint_velocity}"/> -->
      <dynamics damping="0.005" friction="0"/>
    </axis>
    <origin rpy="0 0 0" xyz="0 0 0.08348275862068964"/>
    <parent link="element_25"/>
    <child link="element_26"/>
  </joint>
  <joint name="joint_26_to_27" type="continuous">
    <axis xyz="0 1 0">
      <!-- <limit effort="${joint_effort}" velocity="${joint_velocity}"/> -->
      <dynamics damping="0.005" friction="0"/>
    </axis>
    <origin rpy="0 0 0" xyz="0 0 0.08348275862068964"/>
    <parent link="element_26"/>
    <child link="element_27"/>
  </joint>
  <joint name="joint_27_to_28" type="continuous">
    <axis xyz="0 1 0">
      <!-- <limit effort="${joint_effort}" velocity="${joint_velocity}"/> -->
      <dynamics damping="0.005" friction="0"/>
    </axis>
    <origin rpy="0 0 0" xyz="0 0 0.08348275862068964"/>
    <parent link="element_27"/>
    <child link="element_28"/>
  </joint>
  <joint name="joint_28_to_29" type="continuous">
    <axis xyz="0 1 0">
      <!-- <limit effort="${joint_effort}" velocity="${joint_velocity}"/> -->
      <dynamics damping="0.005" friction="0"/>
    </axis>
    <origin rpy="0 0 0" xyz="0 0 0.08348275862068964"/>
    <parent link="element_28"/>
    <child link="element_29"/>
  </joint>
  <link name="element_first">
    <inertial>
      <origin rpy="0 0 0" xyz="0 0 5e-05"/>
      <mass value="0.0001"/>
      <inertia ixx="2.4033333333333333e-10" ixy="0" ixz="0" iyy="2.4033333333333333e-10" iyz="0" izz="4.805e-10"/>
    </inertial>
    <visual>
      <origin rpy="0 0 0" xyz="0 0 5e-05"/>
      <geometry>
        <cylinder length="0.0001" radius="0.0031"/>
      </geometry>
    </visual>
    <!-- <collision>
        <origin xyz="0 0 ${elem_length/2}" rpy="0 0 0"/>
        <geometry>
          <cylinder length="${elem_length}" radius="0.0031"/>
        </geometry>
      </collision> -->
  </link>
  <link name="element_last">
    <inertial>
      <origin rpy="0 0 0" xyz="0 0 5e-05"/>
      <mass value="0.0001"/>
      <inertia ixx="2.4033333333333333e-10" ixy="0" ixz="0" iyy="2.4033333333333333e-10" iyz="0" izz="4.805e-10"/>
    </inertial>
    <visual>
      <origin rpy="0 0 0" xyz="0 0 5e-05"/>
      <geometry>
        <cylinder length="0.0001" radius="0.0031"/>
      </geometry>
    </visual>
    <!-- <collision>
        <origin xyz="0 0 ${elem_length/2}" rpy="0 0 0"/>
        <geometry>
          <cylinder length="${elem_length}" radius="0.0031"/>
        </geometry>
      </collision> -->
  </link>
  <!-- First to element_1 -->
  <joint name="joint_0_to_1" type="continuous">
    <axis xyz="0 1 0">
      <!-- <limit effort="${joint_effort}" velocity="${joint_velocity}"/> -->
      <dynamics damping="0.005" friction="0"/>
    </axis>
    <origin rpy="0 0 0" xyz="0 0 0.0001"/>
    <parent link="element_first"/>
    <child link="element_1"/>
  </joint>
  <!-- Last interior to endcap -->
  <joint name="joint_29_to_30" type="continuous">
    <axis xyz="0 1 0">
      <!-- <limit effort="${joint_effort}" velocity="${joint_velocity}"/> -->
      <dynamics damping="0.005" friction="0"/>
    </axis>
    <origin rpy="0 0 0" xyz="0 0 0.08348275862068964"/>
    <parent link="element_29"/>
    <child link="element_last"/>
  </joint>
</robot>
