<?xml version="1.0" ?>
<!-- =================================================================================== -->
<!-- |    This document was autogenerated by xacro from model.xacro                    | -->
<!-- |    EDITING THIS FILE BY HAND IS NOT RECOMMENDED                                 | -->
<!-- =================================================================================== -->
<robot name="tether">
  <!-- Xacro to generate tether SDF -->
  <!-- Note: need to manually find and replace all references to 'revolute'
    with 'universal' in final SDF to get better tether. This also involves adding in a second axis.
    These changes are now all defined in generate_sdf.sh-->
  <!--5-->
  <link name="element_1">
    <inertial>
      <origin rpy="0 1.5707963267948966 0" xyz="0.7 0 0"/>
      <mass value="0.02"/>
      <inertia ixx="0.003267166666666666" ixy="0" ixz="0" iyy="0.003267166666666666" iyz="0" izz="1.0000000000000002e-06"/>
    </inertial>
    <visual>
      <origin rpy="0 1.5707963267948966 0" xyz="0.7 0 0"/>
      <geometry>
        <cylinder length="1.4" radius="0.01"/>
      </geometry>
    </visual>
    <!-- <collision>
                <origin xyz="${elem_length/2} 0 0" rpy="0 ${pi/2} 0" />
                <geometry>
                    <cylinder length="${elem_length}" radius="${tether_radius}"/> 0.0001
                </geometry>
            </collision> -->
  </link>
  <link name="element_first">
    <inertial>
      <origin rpy="0 1.5707963267948966 0" xyz="5e-05 0 0"/>
      <mass value="0.0001"/>
      <inertia ixx="2.5000833333333336e-09" ixy="0" ixz="0" iyy="2.5000833333333336e-09" iyz="0" izz="5e-09"/>
    </inertial>
    <visual>
      <origin rpy="0 1.5707963267948966 0" xyz="5e-05 0 0"/>
      <geometry>
        <cylinder length="0.0001" radius="0.01"/>
      </geometry>
    </visual>
    <!-- <collision>
                <origin xyz="${elem_length/2} 0 0" rpy="0 ${pi/2} 0" />
                <geometry>
                    <cylinder length="${elem_length}" radius="${tether_radius}"/> 0.0001
                </geometry>
            </collision> -->
  </link>
  <link name="element_last">
    <inertial>
      <origin rpy="0 1.5707963267948966 0" xyz="5e-05 0 0"/>
      <mass value="0.0001"/>
      <inertia ixx="2.5000833333333336e-09" ixy="0" ixz="0" iyy="2.5000833333333336e-09" iyz="0" izz="5e-09"/>
    </inertial>
    <visual>
      <origin rpy="0 1.5707963267948966 0" xyz="5e-05 0 0"/>
      <geometry>
        <cylinder length="0.0001" radius="0.01"/>
      </geometry>
    </visual>
    <!-- <collision>
                <origin xyz="${elem_length/2} 0 0" rpy="0 ${pi/2} 0" />
                <geometry>
                    <cylinder length="${elem_length}" radius="${tether_radius}"/> 0.0001
                </geometry>
            </collision> -->
  </link>
  <joint name="joint_0_to_1" type="continuous">
    <axis xyz="0. 1. 0."/>
    <origin rpy="0 0.0 0" xyz="0.0001 0 0"/>
    <parent link="element_first"/>
    <child link="element_1"/>
    <dynamics damping="0.01" friction="0"/>
  </joint>
  <joint name="joint_1_to_2" type="continuous">
    <axis xyz="0. 1. 0."/>
    <origin rpy="0 0.0 0" xyz="1.4 0 0"/>
    <parent link="element_1"/>
    <child link="element_last"/>
    <dynamics damping="0.01" friction="0"/>
  </joint>
</robot>
