<sdf version='1.10'>
  <model name='tether_2m'>
    <link name='element_first'>
      <inertial>
        <pose>5.0000000000000002e-05 0 0 0 1.5707963267948966 0</pose>
        <mass>0.0001</mass>
        <inertia>
          <ixx>2.4033333333333338e-10</ixx>
          <ixy>0</ixy>
          <ixz>0</ixz>
          <iyy>2.4033333333333338e-10</iyy>
          <iyz>0</iyz>
          <izz>4.8050000000000005e-10</izz>
        </inertia>
      </inertial>
      <visual name='element_first_visual'>
        <pose>5.0000000000000002e-05 0 0 0 1.5707963267948966 0</pose>
        <geometry>
          <cylinder>
            <length>0.0001</length>
            <radius>0.0030999999999999999</radius>
          </cylinder>
        </geometry>
      </visual>
    </link>
    <joint name='joint_0_to_1' type='universal'>
      <pose relative_to='element_first'>0.0001 0 0 0 1.4660765716752395 0</pose>
      <parent>element_first</parent>
      <child>element_1</child>
      
      <axis>
        <xyz>0 1 0</xyz>
        <limit>
          <lower>-inf</lower>
          <upper>inf</upper>
        </limit>
        <dynamics>
          <damping>0.002</damping>
          <friction>0.0</friction>
          <spring_reference> 0 </spring_reference>
          <spring_stiffness> 0 </spring_stiffness>
        </dynamics>
    </axis>
      <axis2>
        <xyz>0 0 1</xyz>
        <limit>
          <lower>-inf</lower>
          <upper>inf</upper>
        </limit>
        <dynamics>
          <damping>0.002</damping>
          <friction>0.0</friction>
          <spring_reference> 0 </spring_reference>
          <spring_stiffness> 0 </spring_stiffness>
        </dynamics>
      </axis2>
    </joint>
    <link name='element_1'>
      <pose relative_to='joint_0_to_1'>0 0 0 0 0 0</pose>
      <inertial>
        <pose>0.080699999999999994 0 0 0 1.5707963267948966 0</pose>
        <mass>0.0013333333333333331</mass>
        <inertia>
          <ixx>2.8976433333333328e-06</ixx>
          <ixy>0</ixy>
          <ixz>0</ixz>
          <iyy>2.8976433333333328e-06</iyy>
          <iyz>0</iyz>
          <izz>6.4066666666666656e-09</izz>
        </inertia>
      </inertial>
      <visual name='element_1_visual'>
        <pose>0.080699999999999994 0 0 0 1.5707963267948966 0</pose>
        <geometry>
          <cylinder>
            <length>0.16139999999999999</length>
            <radius>0.0030999999999999999</radius>
          </cylinder>
        </geometry>
      </visual>
    </link>
    <joint name='joint_1_to_2' type='universal'>
      <pose relative_to='element_1'>0.16139999999999999 0 0 0 -0.20943951023931962 0</pose>
      <parent>element_1</parent>
      <child>element_2</child>
      
      <axis>
        <xyz>0 1 0</xyz>
        <limit>
          <lower>-inf</lower>
          <upper>inf</upper>
        </limit>
        <dynamics>
          <damping>0.002</damping>
          <friction>0</friction>
          <spring_reference>-0.10833078115</spring_reference>
          <spring_stiffness>0</spring_stiffness>
        </dynamics>
    </axis>
      <axis2>
        <xyz>0 0 1</xyz>
        <limit>
          <lower>-inf</lower>
          <upper>inf</upper>
        </limit>
        <dynamics>
          <damping>0.002</damping>
          <friction>0</friction>
          <spring_reference>0</spring_reference>
          <spring_stiffness>0</spring_stiffness>
        </dynamics>
      </axis2>
    </joint>
    <link name='element_2'>
      <pose relative_to='joint_1_to_2'>0 0 0 0 0 0</pose>
      <inertial>
        <pose>0.080699999999999994 0 0 0 1.5707963267948966 0</pose>
        <mass>0.0013333333333333331</mass>
        <inertia>
          <ixx>2.8976433333333328e-06</ixx>
          <ixy>0</ixy>
          <ixz>0</ixz>
          <iyy>2.8976433333333328e-06</iyy>
          <iyz>0</iyz>
          <izz>6.4066666666666656e-09</izz>
        </inertia>
      </inertial>
      <visual name='element_2_visual'>
        <pose>0.080699999999999994 0 0 0 1.5707963267948966 0</pose>
        <geometry>
          <cylinder>
            <length>0.16139999999999999</length>
            <radius>0.0030999999999999999</radius>
          </cylinder>
        </geometry>
      </visual>
    </link>
    <joint name='joint_2_to_3' type='universal'>
      <pose relative_to='element_2'>0.16139999999999999 0 0 0 -0.20943951023931962 0</pose>
      <parent>element_2</parent>
      <child>element_3</child>
      
      <axis>
        <xyz>0 1 0</xyz>
        <limit>
          <lower>-inf</lower>
          <upper>inf</upper>
        </limit>
        <dynamics>
          <damping>0.002</damping>
          <friction>0.0</friction>
          <spring_reference>-0.10833078115</spring_reference>
          <spring_stiffness>0</spring_stiffness>
        </dynamics>
    </axis>
      <axis2>
        <xyz>0 0 1</xyz>
        <limit>
          <lower>-inf</lower>
          <upper>inf</upper>
        </limit>
        <dynamics>
          <damping>0.002</damping>
          <friction>0.0</friction>
          <spring_reference>0</spring_reference>
          <spring_stiffness>0</spring_stiffness>
        </dynamics>
      </axis2>
    </joint>
    <link name='element_3'>
      <pose relative_to='joint_2_to_3'>0 0 0 0 0 0</pose>
      <inertial>
        <pose>0.080699999999999994 0 0 0 1.5707963267948966 0</pose>
        <mass>0.0013333333333333331</mass>
        <inertia>
          <ixx>2.8976433333333328e-06</ixx>
          <ixy>0</ixy>
          <ixz>0</ixz>
          <iyy>2.8976433333333328e-06</iyy>
          <iyz>0</iyz>
          <izz>6.4066666666666656e-09</izz>
        </inertia>
      </inertial>
      <visual name='element_3_visual'>
        <pose>0.080699999999999994 0 0 0 1.5707963267948966 0</pose>
        <geometry>
          <cylinder>
            <length>0.16139999999999999</length>
            <radius>0.0030999999999999999</radius>
          </cylinder>
        </geometry>
      </visual>
    </link>
    <joint name='joint_3_to_4' type='universal'>
      <pose relative_to='element_3'>0.16139999999999999 0 0 0 -0.20943951023931962 0</pose>
      <parent>element_3</parent>
      <child>element_4</child>
      
      <axis>
        <xyz>0 1 0</xyz>
        <limit>
          <lower>-inf</lower>
          <upper>inf</upper>
        </limit>
        <dynamics>
          <damping>0.002</damping>
          <friction>0</friction>
          <spring_reference>-0.10833078115</spring_reference>
          <spring_stiffness>0</spring_stiffness>
        </dynamics>
    </axis>
      <axis2>
        <xyz>0 0 1</xyz>
        <limit>
          <lower>-inf</lower>
          <upper>inf</upper>
        </limit>
        <dynamics>
          <damping>0.002</damping>
          <friction>0</friction>
          <spring_reference>0</spring_reference>
          <spring_stiffness>0</spring_stiffness>
        </dynamics>
      </axis2>
    </joint>
    <link name='element_4'>
      <pose relative_to='joint_3_to_4'>0 0 0 0 0 0</pose>
      <inertial>
        <pose>0.080699999999999994 0 0 0 1.5707963267948966 0</pose>
        <mass>0.0013333333333333331</mass>
        <inertia>
          <ixx>2.8976433333333328e-06</ixx>
          <ixy>0</ixy>
          <ixz>0</ixz>
          <iyy>2.8976433333333328e-06</iyy>
          <iyz>0</iyz>
          <izz>6.4066666666666656e-09</izz>
        </inertia>
      </inertial>
      <visual name='element_4_visual'>
        <pose>0.080699999999999994 0 0 0 1.5707963267948966 0</pose>
        <geometry>
          <cylinder>
            <length>0.16139999999999999</length>
            <radius>0.0030999999999999999</radius>
          </cylinder>
        </geometry>
      </visual>
    </link>
    <joint name='joint_4_to_5' type='universal'>
      <pose relative_to='element_4'>0.16139999999999999 0 0 0 -0.20943951023931962 0</pose>
      <parent>element_4</parent>
      <child>element_5</child>
      
      <axis>
        <xyz>0 1 0</xyz>
        <limit>
          <lower>-inf</lower>
          <upper>inf</upper>
        </limit>
        <dynamics>
          <damping>0.002</damping>
          <friction>0.0</friction>
          <spring_reference>-0.10833078115</spring_reference>
          <spring_stiffness>0</spring_stiffness>
        </dynamics>
    </axis>
      <axis2>
        <xyz>0 0 1</xyz>
        <limit>
          <lower>-inf</lower>
          <upper>inf</upper>
        </limit>
        <dynamics>
          <damping>0.002</damping>
          <friction>0.0</friction>
          <spring_reference>0</spring_reference>
          <spring_stiffness>0</spring_stiffness>
        </dynamics>
      </axis2>
    </joint>
    <link name='element_5'>
      <pose relative_to='joint_4_to_5'>0 0 0 0 0 0</pose>
      <inertial>
        <pose>0.080699999999999994 0 0 0 1.5707963267948966 0</pose>
        <mass>0.0013333333333333331</mass>
        <inertia>
          <ixx>2.8976433333333328e-06</ixx>
          <ixy>0</ixy>
          <ixz>0</ixz>
          <iyy>2.8976433333333328e-06</iyy>
          <iyz>0</iyz>
          <izz>6.4066666666666656e-09</izz>
        </inertia>
      </inertial>
      <visual name='element_5_visual'>
        <pose>0.080699999999999994 0 0 0 1.5707963267948966 0</pose>
        <geometry>
          <cylinder>
            <length>0.16139999999999999</length>
            <radius>0.0030999999999999999</radius>
          </cylinder>
        </geometry>
      </visual>
    </link>
    <joint name='joint_5_to_6' type='universal'>
      <pose relative_to='element_5'>0.16139999999999999 0 0 0 -0.20943951023931962 0</pose>
      <parent>element_5</parent>
      <child>element_6</child>
      
      <axis>
        <xyz>0 1 0</xyz>
        <limit>
          <lower>-inf</lower>
          <upper>inf</upper>
        </limit>
        <dynamics>
          <damping>0.002</damping>
          <friction>0</friction>
          <spring_reference>-0.10833078115</spring_reference>
          <spring_stiffness>0</spring_stiffness>
        </dynamics>
    </axis>
      <axis2>
        <xyz>0 0 1</xyz>
        <limit>
          <lower>-inf</lower>
          <upper>inf</upper>
        </limit>
        <dynamics>
          <damping>0.002</damping>
          <friction>0</friction>
          <spring_reference>0</spring_reference>
          <spring_stiffness>0</spring_stiffness>
        </dynamics>
      </axis2>
    </joint>
    <link name='element_6'>
      <pose relative_to='joint_5_to_6'>0 0 0 0 0 0</pose>
      <inertial>
        <pose>0.080699999999999994 0 0 0 1.5707963267948966 0</pose>
        <mass>0.0013333333333333331</mass>
        <inertia>
          <ixx>2.8976433333333328e-06</ixx>
          <ixy>0</ixy>
          <ixz>0</ixz>
          <iyy>2.8976433333333328e-06</iyy>
          <iyz>0</iyz>
          <izz>6.4066666666666656e-09</izz>
        </inertia>
      </inertial>
      <visual name='element_6_visual'>
        <pose>0.080699999999999994 0 0 0 1.5707963267948966 0</pose>
        <geometry>
          <cylinder>
            <length>0.16139999999999999</length>
            <radius>0.0030999999999999999</radius>
          </cylinder>
        </geometry>
      </visual>
    </link>
    <joint name='joint_6_to_7' type='universal'>
      <pose relative_to='element_6'>0.16139999999999999 0 0 0 -0.20943951023931962 0</pose>
      <parent>element_6</parent>
      <child>element_7</child>
      
      <axis>
        <xyz>0 1 0</xyz>
        <limit>
          <lower>-inf</lower>
          <upper>inf</upper>
        </limit>
        <dynamics>
          <damping>0.002</damping>
          <friction>0.0</friction>
          <spring_reference>-0.10833078115</spring_reference>
          <spring_stiffness>0</spring_stiffness>
        </dynamics>
    </axis>
      <axis2>
        <xyz>0 0 1</xyz>
        <limit>
          <lower>-inf</lower>
          <upper>inf</upper>
        </limit>
        <dynamics>
          <damping>0.002</damping>
          <friction>0.0</friction>
          <spring_reference>0</spring_reference>
          <spring_stiffness>0</spring_stiffness>
        </dynamics>
      </axis2>
    </joint>
    <link name='element_7'>
      <pose relative_to='joint_6_to_7'>0 0 0 0 0 0</pose>
      <inertial>
        <pose>0.080699999999999994 0 0 0 1.5707963267948966 0</pose>
        <mass>0.0013333333333333331</mass>
        <inertia>
          <ixx>2.8976433333333328e-06</ixx>
          <ixy>0</ixy>
          <ixz>0</ixz>
          <iyy>2.8976433333333328e-06</iyy>
          <iyz>0</iyz>
          <izz>6.4066666666666656e-09</izz>
        </inertia>
      </inertial>
      <visual name='element_7_visual'>
        <pose>0.080699999999999994 0 0 0 1.5707963267948966 0</pose>
        <geometry>
          <cylinder>
            <length>0.16139999999999999</length>
            <radius>0.0030999999999999999</radius>
          </cylinder>
        </geometry>
      </visual>
    </link>
    <joint name='joint_7_to_8' type='universal'>
      <pose relative_to='element_7'>0.16139999999999999 0 0 0 -0.20943951023931962 0</pose>
      <parent>element_7</parent>
      <child>element_8</child>
      
      <axis>
        <xyz>0 1 0</xyz>
        <limit>
          <lower>-inf</lower>
          <upper>inf</upper>
        </limit>
        <dynamics>
          <damping>0.002</damping>
          <friction>0</friction>
          <spring_reference>-0.10833078115</spring_reference>
          <spring_stiffness>0</spring_stiffness>
        </dynamics>
    </axis>
      <axis2>
        <xyz>0 0 1</xyz>
        <limit>
          <lower>-inf</lower>
          <upper>inf</upper>
        </limit>
        <dynamics>
          <damping>0.002</damping>
          <friction>0</friction>
          <spring_reference>0</spring_reference>
          <spring_stiffness>0</spring_stiffness>
        </dynamics>
      </axis2>
    </joint>
    <link name='element_8'>
      <pose relative_to='joint_7_to_8'>0 0 0 0 0 0</pose>
      <inertial>
        <pose>0.080699999999999994 0 0 0 1.5707963267948966 0</pose>
        <mass>0.0013333333333333331</mass>
        <inertia>
          <ixx>2.8976433333333328e-06</ixx>
          <ixy>0</ixy>
          <ixz>0</ixz>
          <iyy>2.8976433333333328e-06</iyy>
          <iyz>0</iyz>
          <izz>6.4066666666666656e-09</izz>
        </inertia>
      </inertial>
      <visual name='element_8_visual'>
        <pose>0.080699999999999994 0 0 0 1.5707963267948966 0</pose>
        <geometry>
          <cylinder>
            <length>0.16139999999999999</length>
            <radius>0.0030999999999999999</radius>
          </cylinder>
        </geometry>
      </visual>
    </link>
    <joint name='joint_8_to_9' type='universal'>
      <pose relative_to='element_8'>0.16139999999999999 0 0 0 -0.20943951023931962 0</pose>
      <parent>element_8</parent>
      <child>element_9</child>
      
      <axis>
        <xyz>0 1 0</xyz>
        <limit>
          <lower>-inf</lower>
          <upper>inf</upper>
        </limit>
        <dynamics>
          <damping>0.002</damping>
          <friction>0.0</friction>
          <spring_reference>-0.10833078115</spring_reference>
          <spring_stiffness>0</spring_stiffness>
        </dynamics>
    </axis>
      <axis2>
        <xyz>0 0 1</xyz>
        <limit>
          <lower>-inf</lower>
          <upper>inf</upper>
        </limit>
        <dynamics>
          <damping>0.002</damping>
          <friction>0.0</friction>
          <spring_reference>0</spring_reference>
          <spring_stiffness>0</spring_stiffness>
        </dynamics>
      </axis2>
    </joint>
    <link name='element_9'>
      <pose relative_to='joint_8_to_9'>0 0 0 0 0 0</pose>
      <inertial>
        <pose>0.080699999999999994 0 0 0 1.5707963267948966 0</pose>
        <mass>0.0013333333333333331</mass>
        <inertia>
          <ixx>2.8976433333333328e-06</ixx>
          <ixy>0</ixy>
          <ixz>0</ixz>
          <iyy>2.8976433333333328e-06</iyy>
          <iyz>0</iyz>
          <izz>6.4066666666666656e-09</izz>
        </inertia>
      </inertial>
      <visual name='element_9_visual'>
        <pose>0.080699999999999994 0 0 0 1.5707963267948966 0</pose>
        <geometry>
          <cylinder>
            <length>0.16139999999999999</length>
            <radius>0.0030999999999999999</radius>
          </cylinder>
        </geometry>
      </visual>
    </link>
    <joint name='joint_9_to_10' type='universal'>
      <pose relative_to='element_9'>0.16139999999999999 0 0 0 -0.20943951023931962 0</pose>
      <parent>element_9</parent>
      <child>element_10</child>
      
      <axis>
        <xyz>0 1 0</xyz>
        <limit>
          <lower>-inf</lower>
          <upper>inf</upper>
        </limit>
        <dynamics>
          <damping>0.002</damping>
          <friction>0</friction>
          <spring_reference>-0.10833078115</spring_reference>
          <spring_stiffness>0</spring_stiffness>
        </dynamics>
    </axis>
      <axis2>
        <xyz>0 0 1</xyz>
        <limit>
          <lower>-inf</lower>
          <upper>inf</upper>
        </limit>
        <dynamics>
          <damping>0.002</damping>
          <friction>0</friction>
          <spring_reference>0</spring_reference>
          <spring_stiffness>0</spring_stiffness>
        </dynamics>
      </axis2>
    </joint>
    <link name='element_10'>
      <pose relative_to='joint_9_to_10'>0 0 0 0 0 0</pose>
      <inertial>
        <pose>0.080699999999999994 0 0 0 1.5707963267948966 0</pose>
        <mass>0.0013333333333333331</mass>
        <inertia>
          <ixx>2.8976433333333328e-06</ixx>
          <ixy>0</ixy>
          <ixz>0</ixz>
          <iyy>2.8976433333333328e-06</iyy>
          <iyz>0</iyz>
          <izz>6.4066666666666656e-09</izz>
        </inertia>
      </inertial>
      <visual name='element_10_visual'>
        <pose>0.080699999999999994 0 0 0 1.5707963267948966 0</pose>
        <geometry>
          <cylinder>
            <length>0.16139999999999999</length>
            <radius>0.0030999999999999999</radius>
          </cylinder>
        </geometry>
      </visual>
    </link>
    <joint name='joint_10_to_11' type='universal'>
      <pose relative_to='element_10'>0.16139999999999999 0 0 0 -0.20943951023931962 0</pose>
      <parent>element_10</parent>
      <child>element_11</child>
      
      <axis>
        <xyz>0 1 0</xyz>
        <limit>
          <lower>-inf</lower>
          <upper>inf</upper>
        </limit>
        <dynamics>
          <damping>0.002</damping>
          <friction>0.0</friction>
          <spring_reference>-0.10833078115</spring_reference>
          <spring_stiffness>0</spring_stiffness>
        </dynamics>
    </axis>
      <axis2>
        <xyz>0 0 1</xyz>
        <limit>
          <lower>-inf</lower>
          <upper>inf</upper>
        </limit>
        <dynamics>
          <damping>0.002</damping>
          <friction>0.0</friction>
          <spring_reference>0</spring_reference>
          <spring_stiffness>0</spring_stiffness>
        </dynamics>
      </axis2>
    </joint>
    <link name='element_11'>
      <pose relative_to='joint_10_to_11'>0 0 0 0 0 0</pose>
      <inertial>
        <pose>0.080699999999999994 0 0 0 1.5707963267948966 0</pose>
        <mass>0.0013333333333333331</mass>
        <inertia>
          <ixx>2.8976433333333328e-06</ixx>
          <ixy>0</ixy>
          <ixz>0</ixz>
          <iyy>2.8976433333333328e-06</iyy>
          <iyz>0</iyz>
          <izz>6.4066666666666656e-09</izz>
        </inertia>
      </inertial>
      <visual name='element_11_visual'>
        <pose>0.080699999999999994 0 0 0 1.5707963267948966 0</pose>
        <geometry>
          <cylinder>
            <length>0.16139999999999999</length>
            <radius>0.0030999999999999999</radius>
          </cylinder>
        </geometry>
      </visual>
    </link>
    <joint name='joint_11_to_12' type='universal'>
      <pose relative_to='element_11'>0.16139999999999999 0 0 0 -0.20943951023931962 0</pose>
      <parent>element_11</parent>
      <child>element_12</child>
      
      <axis>
        <xyz>0 1 0</xyz>
        <limit>
          <lower>-inf</lower>
          <upper>inf</upper>
        </limit>
        <dynamics>
          <damping>0.002</damping>
          <friction>0</friction>
          <spring_reference>-0.10833078115</spring_reference>
          <spring_stiffness>0</spring_stiffness>
        </dynamics>
    </axis>
      <axis2>
        <xyz>0 0 1</xyz>
        <limit>
          <lower>-inf</lower>
          <upper>inf</upper>
        </limit>
        <dynamics>
          <damping>0.002</damping>
          <friction>0</friction>
          <spring_reference>0</spring_reference>
          <spring_stiffness>0</spring_stiffness>
        </dynamics>
      </axis2>
    </joint>
    <link name='element_12'>
      <pose relative_to='joint_11_to_12'>0 0 0 0 0 0</pose>
      <inertial>
        <pose>0.080699999999999994 0 0 0 1.5707963267948966 0</pose>
        <mass>0.0013333333333333331</mass>
        <inertia>
          <ixx>2.8976433333333328e-06</ixx>
          <ixy>0</ixy>
          <ixz>0</ixz>
          <iyy>2.8976433333333328e-06</iyy>
          <iyz>0</iyz>
          <izz>6.4066666666666656e-09</izz>
        </inertia>
      </inertial>
      <visual name='element_12_visual'>
        <pose>0.080699999999999994 0 0 0 1.5707963267948966 0</pose>
        <geometry>
          <cylinder>
            <length>0.16139999999999999</length>
            <radius>0.0030999999999999999</radius>
          </cylinder>
        </geometry>
      </visual>
    </link>
    <joint name='joint_12_to_13' type='universal'>
      <pose relative_to='element_12'>0.16139999999999999 0 0 0 -0.20943951023931962 0</pose>
      <parent>element_12</parent>
      <child>element_13</child>
      
      <axis>
        <xyz>0 1 0</xyz>
        <limit>
          <lower>-inf</lower>
          <upper>inf</upper>
        </limit>
        <dynamics>
          <damping>0.002</damping>
          <friction>0.0</friction>
          <spring_reference>-0.10833078115</spring_reference>
          <spring_stiffness>0</spring_stiffness>
        </dynamics>
    </axis>
      <axis2>
        <xyz>0 0 1</xyz>
        <limit>
          <lower>-inf</lower>
          <upper>inf</upper>
        </limit>
        <dynamics>
          <damping>0.002</damping>
          <friction>0.0</friction>
          <spring_reference>0</spring_reference>
          <spring_stiffness>0</spring_stiffness>
        </dynamics>
      </axis2>
    </joint>
    <link name='element_13'>
      <pose relative_to='joint_12_to_13'>0 0 0 0 0 0</pose>
      <inertial>
        <pose>0.080699999999999994 0 0 0 1.5707963267948966 0</pose>
        <mass>0.0013333333333333331</mass>
        <inertia>
          <ixx>2.8976433333333328e-06</ixx>
          <ixy>0</ixy>
          <ixz>0</ixz>
          <iyy>2.8976433333333328e-06</iyy>
          <iyz>0</iyz>
          <izz>6.4066666666666656e-09</izz>
        </inertia>
      </inertial>
      <visual name='element_13_visual'>
        <pose>0.080699999999999994 0 0 0 1.5707963267948966 0</pose>
        <geometry>
          <cylinder>
            <length>0.16139999999999999</length>
            <radius>0.0030999999999999999</radius>
          </cylinder>
        </geometry>
      </visual>
    </link>
    <joint name='joint_13_to_14' type='universal'>
      <pose relative_to='element_13'>0.16139999999999999 0 0 0 -0.20943951023931962 0</pose>
      <parent>element_13</parent>
      <child>element_14</child>
      
      <axis>
        <xyz>0 1 0</xyz>
        <limit>
          <lower>-inf</lower>
          <upper>inf</upper>
        </limit>
        <dynamics>
          <damping>0.002</damping>
          <friction>0</friction>
          <spring_reference>-0.10833078115</spring_reference>
          <spring_stiffness>0</spring_stiffness>
        </dynamics>
    </axis>
      <axis2>
        <xyz>0 0 1</xyz>
        <limit>
          <lower>-inf</lower>
          <upper>inf</upper>
        </limit>
        <dynamics>
          <damping>0.002</damping>
          <friction>0</friction>
          <spring_reference>0</spring_reference>
          <spring_stiffness>0</spring_stiffness>
        </dynamics>
      </axis2>
    </joint>
    <link name='element_14'>
      <pose relative_to='joint_13_to_14'>0 0 0 0 0 0</pose>
      <inertial>
        <pose>0.080699999999999994 0 0 0 1.5707963267948966 0</pose>
        <mass>0.0013333333333333331</mass>
        <inertia>
          <ixx>2.8976433333333328e-06</ixx>
          <ixy>0</ixy>
          <ixz>0</ixz>
          <iyy>2.8976433333333328e-06</iyy>
          <iyz>0</iyz>
          <izz>6.4066666666666656e-09</izz>
        </inertia>
      </inertial>
      <visual name='element_14_visual'>
        <pose>0.080699999999999994 0 0 0 1.5707963267948966 0</pose>
        <geometry>
          <cylinder>
            <length>0.16139999999999999</length>
            <radius>0.0030999999999999999</radius>
          </cylinder>
        </geometry>
      </visual>
    </link>
    <joint name='joint_14_to_15' type='universal'>
      <pose relative_to='element_14'>0.16139999999999999 0 0 0 -0.20943951023931962 0</pose>
      <parent>element_14</parent>
      <child>element_15</child>
      
      <axis>
        <xyz>0 1 0</xyz>
        <limit>
          <lower>-inf</lower>
          <upper>inf</upper>
        </limit>
        <dynamics>
          <damping>0.002</damping>
          <friction>0.0</friction>
          <spring_reference>-0.10833078115</spring_reference>
          <spring_stiffness>0</spring_stiffness>
        </dynamics>
    </axis>
      <axis2>
        <xyz>0 0 1</xyz>
        <limit>
          <lower>-inf</lower>
          <upper>inf</upper>
        </limit>
        <dynamics>
          <damping>0.002</damping>
          <friction>0.0</friction>
          <spring_reference>0</spring_reference>
          <spring_stiffness>0</spring_stiffness>
        </dynamics>
      </axis2>
    </joint>
    <link name='element_15'>
      <pose relative_to='joint_14_to_15'>0 0 0 0 0 0</pose>
      <inertial>
        <pose>0.080699999999999994 0 0 0 1.5707963267948966 0</pose>
        <mass>0.0013333333333333331</mass>
        <inertia>
          <ixx>2.8976433333333328e-06</ixx>
          <ixy>0</ixy>
          <ixz>0</ixz>
          <iyy>2.8976433333333328e-06</iyy>
          <iyz>0</iyz>
          <izz>6.4066666666666656e-09</izz>
        </inertia>
      </inertial>
      <visual name='element_15_visual'>
        <pose>0.080699999999999994 0 0 0 1.5707963267948966 0</pose>
        <geometry>
          <cylinder>
            <length>0.16139999999999999</length>
            <radius>0.0030999999999999999</radius>
          </cylinder>
        </geometry>
      </visual>
    </link>
    <joint name='joint_15_to_16' type='universal'>
      <pose relative_to='element_15'>0.16139999999999999 0 0 0 1.4660765716752395 0</pose>
      <parent>element_15</parent>
      <child>element_last</child>
      
      <axis>
        <xyz>0 1 0</xyz>
        <limit>
          <lower>-inf</lower>
          <upper>inf</upper>
        </limit>
        <dynamics>
          <damping>0.002</damping>
          <friction>0</friction>
          <spring_reference> 0 </spring_reference>
          <spring_stiffness> 0 </spring_stiffness>
        </dynamics>
    </axis>
      <axis2>
        <xyz>0 0 1</xyz>
        <limit>
          <lower>-inf</lower>
          <upper>inf</upper>
        </limit>
        <dynamics>
          <damping>0.002</damping>
          <friction>0</friction>
          <spring_reference> 0 </spring_reference>
          <spring_stiffness> 0 </spring_stiffness>
        </dynamics>
      </axis2>
    </joint>
    <link name='element_last'>
      <pose relative_to='joint_15_to_16'>0 0 0 0 0 0</pose>
      <inertial>
        <pose>5.0000000000000002e-05 0 0 0 1.5707963267948966 0</pose>
        <mass>0.0001</mass>
        <inertia>
          <ixx>2.4033333333333338e-10</ixx>
          <ixy>0</ixy>
          <ixz>0</ixz>
          <iyy>2.4033333333333338e-10</iyy>
          <iyz>0</iyz>
          <izz>4.8050000000000005e-10</izz>
        </inertia>
      </inertial>
      <visual name='element_last_visual'>
        <pose>5.0000000000000002e-05 0 0 0 1.5707963267948966 0</pose>
        <geometry>
          <cylinder>
            <length>0.0001</length>
            <radius>0.0030999999999999999</radius>
          </cylinder>
        </geometry>
      </visual>
    </link>
  </model>
</sdf>
