<?xml version="1.0" ?>
<!-- =================================================================================== -->
<!-- |    This document was autogenerated by xacro from model.xacro                    | -->
<!-- |    EDITING THIS FILE BY HAND IS NOT RECOMMENDED                                 | -->
<!-- =================================================================================== -->
<robot name="tether_2m">
  <!-- <xacro:property name="joint_effort"   value="1000" />
  <xacro:property name="joint_velocity" value="1000" /> -->
  <link name="element_10">
    <inertial>
      <origin rpy="0 0 0" xyz="0 0 0.12104999999999999"/>
      <mass value="0.002"/>
      <inertia ixx="9.773539999999998e-06" ixy="0" ixz="0" iyy="9.773539999999998e-06" iyz="0" izz="9.61e-09"/>
    </inertial>
    <visual>
      <origin rpy="0 0 0" xyz="0 0 0.12104999999999999"/>
      <geometry>
        <cylinder length="0.24209999999999998" radius="0.0031"/>
      </geometry>
    </visual>
    <!-- <collision>
        <origin xyz="0 0 ${elem_length/2}" rpy="0 0 0"/>
        <geometry>
          <cylinder length="${elem_length}" radius="0.0031"/>
        </geometry>
      </collision> -->
  </link>
  <link name="element_9">
    <inertial>
      <origin rpy="0 0 0" xyz="0 0 0.12104999999999999"/>
      <mass value="0.002"/>
      <inertia ixx="9.773539999999998e-06" ixy="0" ixz="0" iyy="9.773539999999998e-06" iyz="0" izz="9.61e-09"/>
    </inertial>
    <visual>
      <origin rpy="0 0 0" xyz="0 0 0.12104999999999999"/>
      <geometry>
        <cylinder length="0.24209999999999998" radius="0.0031"/>
      </geometry>
    </visual>
    <!-- <collision>
        <origin xyz="0 0 ${elem_length/2}" rpy="0 0 0"/>
        <geometry>
          <cylinder length="${elem_length}" radius="0.0031"/>
        </geometry>
      </collision> -->
  </link>
  <link name="element_8">
    <inertial>
      <origin rpy="0 0 0" xyz="0 0 0.12104999999999999"/>
      <mass value="0.002"/>
      <inertia ixx="9.773539999999998e-06" ixy="0" ixz="0" iyy="9.773539999999998e-06" iyz="0" izz="9.61e-09"/>
    </inertial>
    <visual>
      <origin rpy="0 0 0" xyz="0 0 0.12104999999999999"/>
      <geometry>
        <cylinder length="0.24209999999999998" radius="0.0031"/>
      </geometry>
    </visual>
    <!-- <collision>
        <origin xyz="0 0 ${elem_length/2}" rpy="0 0 0"/>
        <geometry>
          <cylinder length="${elem_length}" radius="0.0031"/>
        </geometry>
      </collision> -->
  </link>
  <link name="element_7">
    <inertial>
      <origin rpy="0 0 0" xyz="0 0 0.12104999999999999"/>
      <mass value="0.002"/>
      <inertia ixx="9.773539999999998e-06" ixy="0" ixz="0" iyy="9.773539999999998e-06" iyz="0" izz="9.61e-09"/>
    </inertial>
    <visual>
      <origin rpy="0 0 0" xyz="0 0 0.12104999999999999"/>
      <geometry>
        <cylinder length="0.24209999999999998" radius="0.0031"/>
      </geometry>
    </visual>
    <!-- <collision>
        <origin xyz="0 0 ${elem_length/2}" rpy="0 0 0"/>
        <geometry>
          <cylinder length="${elem_length}" radius="0.0031"/>
        </geometry>
      </collision> -->
  </link>
  <link name="element_6">
    <inertial>
      <origin rpy="0 0 0" xyz="0 0 0.12104999999999999"/>
      <mass value="0.002"/>
      <inertia ixx="9.773539999999998e-06" ixy="0" ixz="0" iyy="9.773539999999998e-06" iyz="0" izz="9.61e-09"/>
    </inertial>
    <visual>
      <origin rpy="0 0 0" xyz="0 0 0.12104999999999999"/>
      <geometry>
        <cylinder length="0.24209999999999998" radius="0.0031"/>
      </geometry>
    </visual>
    <!-- <collision>
        <origin xyz="0 0 ${elem_length/2}" rpy="0 0 0"/>
        <geometry>
          <cylinder length="${elem_length}" radius="0.0031"/>
        </geometry>
      </collision> -->
  </link>
  <link name="element_5">
    <inertial>
      <origin rpy="0 0 0" xyz="0 0 0.12104999999999999"/>
      <mass value="0.002"/>
      <inertia ixx="9.773539999999998e-06" ixy="0" ixz="0" iyy="9.773539999999998e-06" iyz="0" izz="9.61e-09"/>
    </inertial>
    <visual>
      <origin rpy="0 0 0" xyz="0 0 0.12104999999999999"/>
      <geometry>
        <cylinder length="0.24209999999999998" radius="0.0031"/>
      </geometry>
    </visual>
    <!-- <collision>
        <origin xyz="0 0 ${elem_length/2}" rpy="0 0 0"/>
        <geometry>
          <cylinder length="${elem_length}" radius="0.0031"/>
        </geometry>
      </collision> -->
  </link>
  <link name="element_4">
    <inertial>
      <origin rpy="0 0 0" xyz="0 0 0.12104999999999999"/>
      <mass value="0.002"/>
      <inertia ixx="9.773539999999998e-06" ixy="0" ixz="0" iyy="9.773539999999998e-06" iyz="0" izz="9.61e-09"/>
    </inertial>
    <visual>
      <origin rpy="0 0 0" xyz="0 0 0.12104999999999999"/>
      <geometry>
        <cylinder length="0.24209999999999998" radius="0.0031"/>
      </geometry>
    </visual>
    <!-- <collision>
        <origin xyz="0 0 ${elem_length/2}" rpy="0 0 0"/>
        <geometry>
          <cylinder length="${elem_length}" radius="0.0031"/>
        </geometry>
      </collision> -->
  </link>
  <link name="element_3">
    <inertial>
      <origin rpy="0 0 0" xyz="0 0 0.12104999999999999"/>
      <mass value="0.002"/>
      <inertia ixx="9.773539999999998e-06" ixy="0" ixz="0" iyy="9.773539999999998e-06" iyz="0" izz="9.61e-09"/>
    </inertial>
    <visual>
      <origin rpy="0 0 0" xyz="0 0 0.12104999999999999"/>
      <geometry>
        <cylinder length="0.24209999999999998" radius="0.0031"/>
      </geometry>
    </visual>
    <!-- <collision>
        <origin xyz="0 0 ${elem_length/2}" rpy="0 0 0"/>
        <geometry>
          <cylinder length="${elem_length}" radius="0.0031"/>
        </geometry>
      </collision> -->
  </link>
  <link name="element_2">
    <inertial>
      <origin rpy="0 0 0" xyz="0 0 0.12104999999999999"/>
      <mass value="0.002"/>
      <inertia ixx="9.773539999999998e-06" ixy="0" ixz="0" iyy="9.773539999999998e-06" iyz="0" izz="9.61e-09"/>
    </inertial>
    <visual>
      <origin rpy="0 0 0" xyz="0 0 0.12104999999999999"/>
      <geometry>
        <cylinder length="0.24209999999999998" radius="0.0031"/>
      </geometry>
    </visual>
    <!-- <collision>
        <origin xyz="0 0 ${elem_length/2}" rpy="0 0 0"/>
        <geometry>
          <cylinder length="${elem_length}" radius="0.0031"/>
        </geometry>
      </collision> -->
  </link>
  <link name="element_1">
    <inertial>
      <origin rpy="0 0 0" xyz="0 0 0.12104999999999999"/>
      <mass value="0.002"/>
      <inertia ixx="9.773539999999998e-06" ixy="0" ixz="0" iyy="9.773539999999998e-06" iyz="0" izz="9.61e-09"/>
    </inertial>
    <visual>
      <origin rpy="0 0 0" xyz="0 0 0.12104999999999999"/>
      <geometry>
        <cylinder length="0.24209999999999998" radius="0.0031"/>
      </geometry>
    </visual>
    <!-- <collision>
        <origin xyz="0 0 ${elem_length/2}" rpy="0 0 0"/>
        <geometry>
          <cylinder length="${elem_length}" radius="0.0031"/>
        </geometry>
      </collision> -->
  </link>
  <joint name="joint_1_to_2" type="continuous">
    <axis xyz="0 1 0">
      <!-- <limit effort="${joint_effort}" velocity="${joint_velocity}"/> -->
      <dynamics damping="0.01" friction="5"/>
    </axis>
    <origin rpy="0 0 0" xyz="0 0 0.24209999999999998"/>
    <parent link="element_1"/>
    <child link="element_2"/>
  </joint>
  <joint name="joint_2_to_3" type="continuous">
    <axis xyz="0 1 0">
      <!-- <limit effort="${joint_effort}" velocity="${joint_velocity}"/> -->
      <dynamics damping="0.01" friction="5"/>
    </axis>
    <origin rpy="0 0 0" xyz="0 0 0.24209999999999998"/>
    <parent link="element_2"/>
    <child link="element_3"/>
  </joint>
  <joint name="joint_3_to_4" type="continuous">
    <axis xyz="0 1 0">
      <!-- <limit effort="${joint_effort}" velocity="${joint_velocity}"/> -->
      <dynamics damping="0.01" friction="5"/>
    </axis>
    <origin rpy="0 0 0" xyz="0 0 0.24209999999999998"/>
    <parent link="element_3"/>
    <child link="element_4"/>
  </joint>
  <joint name="joint_4_to_5" type="continuous">
    <axis xyz="0 1 0">
      <!-- <limit effort="${joint_effort}" velocity="${joint_velocity}"/> -->
      <dynamics damping="0.01" friction="5"/>
    </axis>
    <origin rpy="0 0 0" xyz="0 0 0.24209999999999998"/>
    <parent link="element_4"/>
    <child link="element_5"/>
  </joint>
  <joint name="joint_5_to_6" type="continuous">
    <axis xyz="0 1 0">
      <!-- <limit effort="${joint_effort}" velocity="${joint_velocity}"/> -->
      <dynamics damping="0.01" friction="5"/>
    </axis>
    <origin rpy="0 0 0" xyz="0 0 0.24209999999999998"/>
    <parent link="element_5"/>
    <child link="element_6"/>
  </joint>
  <joint name="joint_6_to_7" type="continuous">
    <axis xyz="0 1 0">
      <!-- <limit effort="${joint_effort}" velocity="${joint_velocity}"/> -->
      <dynamics damping="0.01" friction="5"/>
    </axis>
    <origin rpy="0 0 0" xyz="0 0 0.24209999999999998"/>
    <parent link="element_6"/>
    <child link="element_7"/>
  </joint>
  <joint name="joint_7_to_8" type="continuous">
    <axis xyz="0 1 0">
      <!-- <limit effort="${joint_effort}" velocity="${joint_velocity}"/> -->
      <dynamics damping="0.01" friction="5"/>
    </axis>
    <origin rpy="0 0 0" xyz="0 0 0.24209999999999998"/>
    <parent link="element_7"/>
    <child link="element_8"/>
  </joint>
  <joint name="joint_8_to_9" type="continuous">
    <axis xyz="0 1 0">
      <!-- <limit effort="${joint_effort}" velocity="${joint_velocity}"/> -->
      <dynamics damping="0.01" friction="5"/>
    </axis>
    <origin rpy="0 0 0" xyz="0 0 0.24209999999999998"/>
    <parent link="element_8"/>
    <child link="element_9"/>
  </joint>
  <joint name="joint_9_to_10" type="continuous">
    <axis xyz="0 1 0">
      <!-- <limit effort="${joint_effort}" velocity="${joint_velocity}"/> -->
      <dynamics damping="0.01" friction="5"/>
    </axis>
    <origin rpy="0 0 0" xyz="0 0 0.24209999999999998"/>
    <parent link="element_9"/>
    <child link="element_10"/>
  </joint>
  <link name="element_first">
    <inertial>
      <origin rpy="0 0 0" xyz="0 0 5e-05"/>
      <mass value="0.0001"/>
      <inertia ixx="2.4033333333333333e-10" ixy="0" ixz="0" iyy="2.4033333333333333e-10" iyz="0" izz="4.805e-10"/>
    </inertial>
    <visual>
      <origin rpy="0 0 0" xyz="0 0 5e-05"/>
      <geometry>
        <cylinder length="0.0001" radius="0.0031"/>
      </geometry>
    </visual>
    <!-- <collision>
        <origin xyz="0 0 ${elem_length/2}" rpy="0 0 0"/>
        <geometry>
          <cylinder length="${elem_length}" radius="0.0031"/>
        </geometry>
      </collision> -->
  </link>
  <link name="element_last">
    <inertial>
      <origin rpy="0 0 0" xyz="0 0 5e-05"/>
      <mass value="0.0001"/>
      <inertia ixx="2.4033333333333333e-10" ixy="0" ixz="0" iyy="2.4033333333333333e-10" iyz="0" izz="4.805e-10"/>
    </inertial>
    <visual>
      <origin rpy="0 0 0" xyz="0 0 5e-05"/>
      <geometry>
        <cylinder length="0.0001" radius="0.0031"/>
      </geometry>
    </visual>
    <!-- <collision>
        <origin xyz="0 0 ${elem_length/2}" rpy="0 0 0"/>
        <geometry>
          <cylinder length="${elem_length}" radius="0.0031"/>
        </geometry>
      </collision> -->
  </link>
  <!-- First to element_1 -->
  <joint name="joint_0_to_1" type="continuous">
    <axis xyz="0 1 0">
      <!-- <limit effort="${joint_effort}" velocity="${joint_velocity}"/> -->
      <dynamics damping="0.01" friction="5"/>
    </axis>
    <origin rpy="0 0 0" xyz="0 0 0.0001"/>
    <parent link="element_first"/>
    <child link="element_1"/>
  </joint>
  <!-- Last interior to endcap -->
  <joint name="joint_10_to_11" type="continuous">
    <axis xyz="0 1 0">
      <!-- <limit effort="${joint_effort}" velocity="${joint_velocity}"/> -->
      <dynamics damping="0.01" friction="5"/>
    </axis>
    <origin rpy="0 0 0" xyz="0 0 0.24209999999999998"/>
    <parent link="element_10"/>
    <child link="element_last"/>
  </joint>
</robot>
